<?xml version="1.0"?>
<robot name="sentry" xmlns:xacro="http://ros.org">

  <!-- Define robot constants -->
  <xacro:property name="base_radius" value="0.2975" />
  <xacro:property name="base_height" value="0.220" />
  <xacro:property name="head_length" value="0.29528" />
  <xacro:property name="head_width" value="0.1524" />
  <xacro:property name="head_height" value="0.18398" />

  <!-- Inertial Macros -->
  <xacro:macro name="box_inertia" params="m w h d">
    <inertial>
      <origin xyz="0 0 0" rpy="0 0 0" />
      <mass value="${m}" />
      <inertia ixx="${(m/12) * (h*h + d*d)}" ixy="0.0" ixz="0.0"
        iyy="${(m/12) * (w*w + d*d)}" iyz="0.0"
        izz="${(m/12) * (w*w + h*h)}" />
    </inertial>
  </xacro:macro>

  <!-- 1. Robot Footprint (The Ground Reference) -->
  <link name="base_footprint">
    <inertial>
      <mass value="0.0001" />
      <inertia ixx="0.0001" ixy="0" ixz="0" iyy="0.0001" iyz="0" izz="0.0001" />
    </inertial>
  </link>


  <joint name="base_joint" type="fixed">
    <parent link="base_footprint" />
    <child link="base_link" />
    <origin xyz="0 0 ${base_height/2}" rpy="0 0 0" />
  </joint>

  <!-- 2. Robot Base (The Cylinder) -->
  <link name="base_link">
    <visual>
      <geometry>
        <cylinder radius="${base_radius}" length="${base_height}" />
      </geometry>
      <material name="Dark_Cyan">
        <color rgba="0 0.8 0.8 0.8" />
      </material>
    </visual>
    <collision>
      <geometry>
        <cylinder radius="${base_radius}" length="${base_height}" />
      </geometry>
    </collision>
    <inertial>
      <mass value="5.0" />
      <inertia ixx="0.1" ixy="0" ixz="0" iyy="0.1" iyz="0" izz="0.2" />
    </inertial>
  </link>

  <!-- 3. Robot Head (The Rotating Box) -->
  <joint name="head_joint" type="continuous">
    <parent link="base_link" />
    <child link="head_link" />
    <!-- Centers the head slightly above the top of the base cylinder -->
    <origin xyz="0 0 ${base_height/2 + 0.05}" rpy="0 0 0" />
    <axis xyz="0 0 1" />
  </joint>

  <link name="head_link">
    <visual>
      <geometry>
        <box size="${head_length} ${head_width} ${head_height}" />
      </geometry>
      <material name="Cyan">
        <color rgba="0 1.0 1.0 1.0" />
      </material>
    </visual>
    <collision>
      <geometry>
        <box size="${head_length} ${head_width} ${head_height}" />
      </geometry>
    </collision>
    <xacro:box_inertia m="0.5" w="${head_width}" h="${head_height}" d="${head_length}" />
  </link>

  <joint name="lidar_joint" type="fixed">
    <parent link="head_link" />
    <child link="lidar" />
    <!-- Placed on the front edge of the head -->
    <origin xyz="0.12218 -0.17882 0" rpy="0 0 ${pi/2}" />
  </joint>
  <link name="lidar">
    <visual>
      <geometry>
        <cylinder radius="0.05" length="0.04" />
      </geometry>
      <material name="black">
        <color rgba="0 0 0 1" />
      </material>
    </visual>
    <collision>
      <geometry>
        <cylinder radius="0.05" length="0.04" />
      </geometry>
    </collision>
    <inertial>
      <mass value="0.1" />
      <inertia ixx="0.001" ixy="0" ixz="0" iyy="0.001" iyz="0" izz="0.001" />
    </inertial>
  </link>
  <!-- <gazebo reference="laser"> -->
  <!-- <sensor name="lidar" type="ray"> -->
  <!-- <pose>0 0 0 0 0 0</pose> -->
  <!-- <visualize>true</visualize> -->
  <!-- <update_rate>10</update_rate> -->
  <!-- <ray> -->
  <!-- <scan> -->
  <!-- <horizontal> -->
  <!-- <samples>360</samples> -->
  <!-- <resolution>1</resolution> -->
  <!-- <min_angle>-3.14</min_angle> -->
  <!-- <max_angle>3.14</max_angle> -->
  <!-- </horizontal> -->
  <!-- </scan> -->
  <!-- <range> -->
  <!-- <min>0.3</min> -->
  <!-- <max>12.0</max> -->
  <!-- </range> -->
  <!-- </ray> -->
  <!-- <plugin name="gazebo_ros_ray_sensor" filename="libgazebo_ros_ray_sensor.so"> -->
  <!-- <ros> -->
  <!-- <remapping>~/out:=scan</remapping> -->
  <!-- </ros> -->
  <!-- <output_type>sensor_msgs/LaserScan</output_type> -->
  <!-- <frame_name>laser</frame_name> -->
  <!-- </plugin> -->
  <!-- </sensor> -->
  <!-- </gazebo> -->

</robot>
