<?xml version="1.0"?>
<!--URDF generated by ONSHAPE BY PTC INC, 1.217-->
<robot name="sentry">
  <link name="part_1">
    <inertial>
      <mass value="0.0701287"/>
      <origin xyz="1.20374e-17 2.46519e-32 0.126108" rpy="0 -0 0"/>
      <inertia ixx="0.00192346" ixy="0" ixz="0" iyy="0.00192346" iyz="0" izz="0.00310341"/>
    </inertial>
    <visual>
      <origin xyz="0 -1.82166e-17 0.0734155" rpy="0 -0 0"/>
      <geometry>
        <mesh filename="package://sentry_pkg/meshes/Part_1.stl" scale="1 1 1"/>
      </geometry>
      <material name="0.615686_0.811765_0.929412_0.000000_0.000000">
        <color rgba="0.615686 0.811765 0.929412 1"/>
      </material>
    </visual>
  </link>
  <link name="part_1_1">
    <inertial>
      <mass value="0.00421105"/>
      <origin xyz="0.00100261 -0.00244355 0.0730117" rpy="0 -0 2.48157"/>
      <inertia ixx="1.8557e-05" ixy="4.2327e-06" ixz="1.56708e-08" iyy="1.90292e-05" iyz="-3.81928e-08" izz="2.21682e-05"/>
    </inertial>
    <visual>
      <origin xyz="-1.68946e-18 -2.17675e-18 0" rpy="0 -0 2.48157"/>
      <geometry>
        <mesh filename="package://sentry_pkg/meshes/Part_1_1.stl" scale="1 1 1"/>
      </geometry>
      <material name="0.615686_0.811765_0.929412_0.000000_0.000000">
        <color rgba="0.615686 0.811765 0.929412 1"/>
      </material>
    </visual>
  </link>
  <link name="part_1_2">
    <inertial>
      <mass value="0.00018588"/>
      <origin xyz="-6.05411e-19 -4.2157e-19 0.02065" rpy="0 -0 0.608263"/>
      <inertia ixx="9.29949e-08" ixy="0" ixz="0" iyy="9.29949e-08" iyz="0" izz="1.33148e-07"/>
    </inertial>
    <visual>
      <origin xyz="1.3244e-18 -1.90196e-18 0" rpy="0 -0 0.608263"/>
      <geometry>
        <mesh filename="package://sentry_pkg/meshes/Part_1_2.stl" scale="1 1 1"/>
      </geometry>
      <material name="0.615686_0.811765_0.929412_0.000000_0.000000">
        <color rgba="0.615686 0.811765 0.929412 1"/>
      </material>
    </visual>
  </link>
  <link name="root"/>
  <joint name="fastened_1" type="fixed">
    <origin xyz="0 1.38778e-17 -8.69386e-19" rpy="-1.5708 -0 3.14159"/>
    <axis xyz="0 0 -1"/>
    <parent link="root"/>
    <child link="part_1"/>
  </joint>
  <joint name="headlink" type="continuous">
    <origin xyz="3.00043e-17 -1.82344e-18 0.252215" rpy="0 -0 -3.14159"/>
    <axis xyz="0 0 -1"/>
    <parent link="part_1"/>
    <child link="part_1_1"/>
  </joint>
  <joint name="lidar" type="continuous">
    <origin xyz="0.0884778 -0.20163 0.0718" rpy="0 0 -0.660022"/>
    <axis xyz="0 0 -1"/>
    <parent link="part_1_1"/>
    <child link="part_1_2"/>
  </joint>
  <gazebo>
    <plugin name="gz::sim::systems::Physics" filename="gz-sim-physics-system"/>
    <plugin name="gz::sim::systems::UserCommands" filename="gz-sim-user-commands-system"/>
    <plugin name="gz::sim::systems::SceneBroadcaster" filename="gz-sim-scene-broadcaster-system"/>
  </gazebo>
</robot>
