<?xml version="1.0"?>
<sdf version="1.8" xmlns:xacro="http://ros.org/wiki/xacro">
  <model name='sam_bot' canonical_link='base_link' xmlns:gz="http://gazebosim.org/schema">

  <!-- Define robot constants -->
  <xacro:property name="base_radius" value="0.30"/>
  <xacro:property name="base_height" value="0.216"/>

  <xacro:property name="head_length" value="0.2667"/>
  <xacro:property name="head_width" value="0.1555"/>
  <xacro:property name="head_height" value="0.15875"/>

  <xacro:property name="pitch_turret_length" value="0.15"/>
  <xacro:property name="pitch_turret_width" value="0.10"/>
  <xacro:property name="pitch_turret_height" value="0.10"/>

  <xacro:property name="barrel_radius" value="0.025"/>
  <xacro:property name="barrel_length" value="0.15"/>

   <!-- Define some commonly used intertial properties  -->
  <xacro:macro name="box_inertia" params="m w h d">
    <inertial>
      <pose>0 0 0 ${pi/2} 0 ${pi/2}</pose>
      <mass>${m}</mass>
      <inertia>
        <ixx>${(m/12) * (h*h + d*d)}</ixx>
        <ixy>0.0</ixy>
        <ixz>0.0</ixz>
        <iyy>${(m/12) * (w*w + d*d)}</iyy>
        <iyz>0.0</iyz>
        <izz>${(m/12) * (w*w + h*h)}</izz>
      </inertia>
    </inertial>
  </xacro:macro>

  <xacro:macro name="cylinder_inertia" params="m r h">
    <inertial>
      <pose>0 0 0 ${pi/2} 0 0</pose>
      <mass>${m}</mass>
      <inertia>
        <ixx>${(m/12) * (3*r*r + h*h)}</ixx>
        <ixy>0.0</ixy>
        <ixz>0.0</ixz>
        <iyy>${(m/12) * (3*r*r + h*h)}</iyy>
        <iyz>0.0</iyz>
        <izz>${(m/2) * (r*r)}</izz>
      </inertia>
    </inertial>
  </xacro:macro>


  <xacro:macro name="sphere_inertia" params="m r">
    <inertial>
      <mass>${m}</mass>
      <inertia>
        <ixx>${(2/5) * m * (r*r)}</ixx>
        <ixy>0.0</ixy>
        <ixz>0.0</ixz>
        <iyy>${(2/5) * m * (r*r)}</iyy>
        <iyz>0.0</iyz>
        <izz>${(2/5) * m * (r*r)}</izz>
      </inertia>
    </inertial>
  </xacro:macro>


  <!-- Robot Base -->
  <link name='base_link'>
    <must_be_base_link>true</must_be_base_link>
    <visual name="base_link_visual">
      <geometry>
        <cylinder>
          <radius>${base_radius}</radius>
          <length>${base_height}</length>
        </cylinder>
      </geometry>
      <material>
        <ambient>0 1 1 1</ambient>
        <diffuse>0 1 1 1</diffuse>
      </material>
    </visual>

    <collision name="base_link_collision">
      <geometry>
        <cylinder>
          <radius>${base_radius}</radius>
          <length>${base_height}</length>
        </cylinder>
      </geometry>
    </collision> 

    <xacro:cylinder_inertia m="0.5" r="${base_radius}" h="${base_height}"/>
  </link>

  <!-- Robot Footprint -->
  <link name='base_footprint'>
    <pose relative_to="base_joint"/>
    <xacro:cylinder_inertia m="15" r="${base_radius}" h="${base_height}"/>
  </link>


  <joint name='base_joint' type='fixed'>
    <parent>base_link</parent>
    <child>base_footprint</child>
    <pose relative_to="base_link">0.0 0.0 0.0 0 0 0</pose>
  </joint>


  <!-- Robot Head -->
  <link name='head_link'>
    <pose relative_to="head_joint"/>
    <visual name="head_link_visual">
      <pose relative_to="head_link"/>
      <geometry>
        <box><size>
          ${head_length} ${head_width} ${head_height}
        </size></box>
      </geometry>
      <material>
        <ambient>0 1 1 1</ambient>
        <diffuse>0 1 1 1</diffuse>
      </material>
    </visual>

    <collision name="head_link_collision">
      <pose relative_to="head_link"/>
      <geometry>
        <box><size>
          ${head_length} ${head_width} ${head_height}
        </size></box>
      </geometry>
    </collision> 
  </link>

  <joint name='head_joint' type='fixed'>
  <!-- <joint name='head_joint' type='continuous'> -->
    <parent>base_link</parent>
    <child>head_link</child>
    <pose relative_to="base_link">0.0 0.0 ${(head_height + base_height) / 2} 0 0 0</pose>
    <!-- <axis>
      <xyz>0 0 1</xyz>
      <limit>
        <lower>-inf</lower>
        <upper>inf</upper>
      </limit>
    </axis> -->
  </joint>


  <!-- Robot pitch turret -->
  <link name='pitch_turret_link'>
    <pose relative_to="pitch_turret_joint"/>
    <visual name="pitch_turret_link_visual">
      <pose relative_to="pitch_turret_link"/>
      <geometry>
        <box><size>
          ${pitch_turret_length} ${pitch_turret_width} ${pitch_turret_height}
        </size></box>
      </geometry>
      <material>
        <ambient>0 1 1 1</ambient>
        <diffuse>0 1 1 1</diffuse>
      </material>
    </visual>

    <collision name="pitch_turret_link_collision">
      <pose relative_to="pitch_turret_link"/>
      <geometry>
        <box><size>
          ${pitch_turret_length} ${pitch_turret_width} ${pitch_turret_height}
        </size></box>
      </geometry>
    </collision> 
  </link>

  <joint name='pitch_turret_joint' type='revolute'>
    <parent>head_link</parent>
    <child>pitch_turret_link</child>
    <pose relative_to="head_link">0.0 0.0 0 0 0 0</pose>
    <axis>
      <xyz>1 0 0</xyz>
      <limit>
        <lower>-${pi/12}</lower>
        <upper>${pi/12}</upper>
      </limit>
    </axis>
  </joint>


  <!-- Robot barrel -->
  <link name='barrel_link'>
    <pose relative_to="barrel_joint">0 0 0 ${pi/2} 0 0</pose>
    <visual name="barrel_link_visual">
      <pose relative_to="barrel_link"/>
      <geometry>
        <cylinder>
          <radius>${barrel_radius}</radius>
          <length>${barrel_length}</length>
        </cylinder>
      </geometry>
      <material>
        <ambient>0 1 1 1</ambient>
        <diffuse>0 1 1 1</diffuse>
      </material>
    </visual>

    <collision name="barrel_link_collision">
      <pose relative_to="barrel_link">0 0 0 0 0 0</pose>
      <geometry>
        <cylinder>
          <radius>${barrel_radius}</radius>
          <length>${barrel_length}</length>
        </cylinder>
      </geometry>
    </collision> 

    <xacro:cylinder_inertia m="0.5" r="${barrel_radius}" h="${barrel_length}"/>
  </link>


  <joint name='barrel_joint' type='fixed'>
    <parent>pitch_turret_link</parent>
    <child>barrel_link</child>
    <pose relative_to="head_link">0.0 ${(head_width + base_height)/2} 0.0 0 0 0</pose>
  </joint>

  <link name='front_left_wheel'>
    <pose>0.25 0.25 -0.1 -1.5707 0 0</pose>
    <inertial>
      <mass>2</mass>
      <inertia>
        <ixx>0.145833</ixx>
        <ixy>0</ixy>
        <ixz>0</ixz>
        <iyy>0.145833</iyy>
        <iyz>0</iyz>
        <izz>0.125</izz>
      </inertia>
    </inertial>
    <visual name='visual'>
      <pose>0 0 0 1.5707 0 0</pose>
      <geometry>
        <!-- scale mesh to radius == 0.3 -->
        <mesh>
          <uri>https://fuel.gazebosim.org/1.0/OpenRobotics/models/Mecanum lift/tip/files/meshes/mecanum_wheel_left.STL</uri>
          <scale>0.001 0.001 0.001</scale>
        </mesh>
      </geometry>
      <material>
        <ambient>0.2 0.2 0.2 1</ambient>
        <diffuse>0.2 0.2 0.2 1</diffuse>
        <specular>0.2 0.2 0.2 1</specular>
      </material>
    </visual>
    <collision name='collision'>
      <geometry>
        <sphere>
          <radius>0.05</radius>
        </sphere>
      </geometry>
      <surface>
        <friction>
          <ode>
            <mu>1.0</mu>
            <mu2>0.0</mu2>
            <fdir1 gz:expressed_in="base_link">1 -1 0</fdir1>
          </ode>
        </friction>
      </surface>
    </collision>
  </link>

  <link name='rear_left_wheel'>
    <pose>-0.25 0.25 -0.1 -1.5707 0 0</pose>
    <inertial>
      <mass>2</mass>
      <inertia>
        <ixx>0.145833</ixx>
        <ixy>0</ixy>
        <ixz>0</ixz>
        <iyy>0.145833</iyy>
        <iyz>0</iyz>
        <izz>0.125</izz>
      </inertia>
    </inertial>
    <visual name='visual'>
      <pose>0 0 0 1.5707 0 0</pose>
      <geometry>
        <!-- scale mesh to radius == 0.3 -->
        <mesh>
          <uri>https://fuel.gazebosim.org/1.0/OpenRobotics/models/Mecanum lift/tip/files/meshes/mecanum_wheel_right.STL</uri>
          <scale>0.001 0.001 0.001</scale>
        </mesh>
      </geometry>
      <material>
        <ambient>0.2 0.2 0.2 1</ambient>
        <diffuse>0.2 0.2 0.2 1</diffuse>
        <specular>0.2 0.2 0.2 1</specular>
      </material>
    </visual>
    <collision name='collision'>
      <geometry>
        <sphere>
          <radius>0.05</radius>
        </sphere>
      </geometry>
      <surface>
        <friction>
          <ode>
            <mu>1.0</mu>
            <mu2>0.0</mu2>
            <fdir1 gz:expressed_in="base_link">1 1 0</fdir1>
          </ode>
        </friction>
      </surface>
    </collision>
  </link>

  <link name='front_right_wheel'>
    <pose>0.25 -0.25 -0.1 -1.5707 0 0</pose>
    <inertial>
      <mass>2</mass>
      <inertia>
        <ixx>0.145833</ixx>
        <ixy>0</ixy>
        <ixz>0</ixz>
        <iyy>0.145833</iyy>
        <iyz>0</iyz>
        <izz>0.125</izz>
      </inertia>
    </inertial>
    <visual name='visual'>
      <pose>0 0 0 1.5707 0 0</pose>
      <geometry>
        <!-- scale mesh to radius == 0.3 -->
        <mesh>
          <uri>https://fuel.gazebosim.org/1.0/OpenRobotics/models/Mecanum lift/tip/files/meshes/mecanum_wheel_right.STL</uri>
          <scale>0.001 0.001 0.001</scale>
        </mesh>
      </geometry>
      <material>
        <ambient>0.2 0.2 0.2 1</ambient>
        <diffuse>0.2 0.2 0.2 1</diffuse>
        <specular>0.2 0.2 0.2 1</specular>
      </material>
    </visual>
    <collision name='collision'>
      <geometry>
        <sphere>
          <radius>0.05</radius>
        </sphere>
      </geometry>
      <surface>
        <friction>
          <ode>
            <mu>1.0</mu>
            <mu2>0.0</mu2>
            <fdir1 gz:expressed_in="base_link">1 1 0</fdir1>
          </ode>
        </friction>
      </surface>
    </collision>
  </link>

  <link name='rear_right_wheel'>
    <pose>-0.25 -0.25 -0.1 -1.5707 0 0</pose>
    <inertial>
      <mass>2</mass>
      <inertia>
        <ixx>0.145833</ixx>
        <ixy>0</ixy>
        <ixz>0</ixz>
        <iyy>0.145833</iyy>
        <iyz>0</iyz>
        <izz>0.125</izz>
      </inertia>
    </inertial>
    <visual name='visual'>
      <pose>0 0 0 1.5707 0 0</pose>
      <geometry>
        <!-- scale mesh to radius == 0.3 -->
        <mesh>
          <uri>https://fuel.gazebosim.org/1.0/OpenRobotics/models/Mecanum lift/tip/files/meshes/mecanum_wheel_left.STL</uri>
          <scale>0.001 0.001 0.001</scale>
        </mesh>
      </geometry>
      <material>
        <ambient>0.2 0.2 0.2 1</ambient>
        <diffuse>0.2 0.2 0.2 1</diffuse>
        <specular>0.2 0.2 0.2 1</specular>
      </material>
    </visual>
    <collision name='collision'>
      <geometry>
        <sphere>
          <radius>0.05</radius>
        </sphere>
      </geometry>
      <surface>
        <friction>
          <ode>
            <mu>1.0</mu>
            <mu2>0.0</mu2>
            <fdir1 gz:expressed_in="base_link">1 -1 0</fdir1>
          </ode>
        </friction>
      </surface>
    </collision>
  </link>


  <joint name='front_left_wheel_joint' type='revolute'>
    <parent>base_link</parent>
    <child>front_left_wheel</child>
    <axis>
      <xyz>0 0 1</xyz>
      <limit>
        <lower>-1.79769e+308</lower>
        <upper>1.79769e+308</upper>
      </limit>
    </axis>
  </joint>

  <joint name='front_right_wheel_joint' type='revolute'>
    <parent>base_link</parent>
    <child>front_right_wheel</child>
    <axis>
      <xyz>0 0 1</xyz>
      <limit>
        <lower>-1.79769e+308</lower>
        <upper>1.79769e+308</upper>
      </limit>
    </axis>
  </joint>

  <joint name='rear_left_wheel_joint' type='revolute'>
    <parent>base_link</parent>
    <child>rear_left_wheel</child>
    <axis>
      <xyz>0 0 1</xyz>
      <limit>
        <lower>-1.79769e+308</lower>
        <upper>1.79769e+308</upper>
      </limit>
    </axis>
  </joint>

  <joint name='rear_right_wheel_joint' type='revolute'>
    <parent>base_link</parent>
    <child>rear_right_wheel</child>
    <axis>
      <xyz>0 0 1</xyz>
      <limit>
        <lower>-1.79769e+308</lower>
        <upper>1.79769e+308</upper>
      </limit>
    </axis>
  </joint>

   <!-- gazebo drive controler -->
  <plugin
    filename="gz-sim-mecanum-drive-system"
    name="gz::sim::systems::MecanumDrive">


    <!-- Wheel joints -->
    <front_left_joint>front_left_wheel_joint</front_left_joint>
    <front_right_joint>front_right_wheel_joint</front_right_joint>
    <back_left_joint>rear_left_wheel_joint</back_left_joint>
    <back_right_joint>rear_right_wheel_joint</back_right_joint>

    <!-- Wheel parameters -->
    <wheel_separation>0.5</wheel_separation> <!-- Lateral distance between left and right wheels, in meters -->
    <wheelbase>0.5</wheelbase> <!-- Longitudinal distance between front and back wheels -->
    <wheel_radius>0.05</wheel_radius>

    <!-- Control gains and limits (optional) -->
    <min_acceleration>-5</min_acceleration>
    <max_acceleration>5</max_acceleration>

    <!-- Topic for the command input -->
    <topic>/demo/cmd_vel</topic>

    <!-- Other parameters (optional) -->
    <odom_topic>/demo/odom</odom_topic>
    <tf_topic>/tf</tf_topic>
    <frame_id>odom</frame_id>
    <child_frame_id>base_link</child_frame_id>
    <odom_publish_frequency>30</odom_publish_frequency>
  </plugin>

  <!-- seprate plugin needed with above mecanum to actualy publish odom msg -->
  <plugin name="gz::sim::systems::OdometryPublisher" filename="gz-sim-odometry-publisher-system">
    <odom_topic>/demo/odom</odom_topic>
    <odom_frame>odom</odom_frame>
    <robot_base_frame>base_footprint</robot_base_frame>
    <publish_tf>true</publish_tf>
    <tf_topic>tf</tf_topic>
    <odom_publish_frequency>30</odom_publish_frequency>
    <xyz_offset>0 0 0</xyz_offset>
    <rpy_offset>0 0 0</rpy_offset>
  </plugin>

  <plugin
    filename="gz-sim-joint-state-publisher-system"
    name="gz::sim::systems::JointStatePublisher">
    <topic>joint_states</topic>
  </plugin>

  <!-- IMU -->
  <joint name='imu_joint' type='fixed'>
    <parent>head_link</parent>
    <child>imu_link</child>
    <pose relative_to="head_link">0.0 0.0 0.01 0 0 0</pose>
  </joint>

  <link name='imu_link'>
    <pose relative_to="imu_joint"/>
    <visual name="imu_link_visual">
      <geometry>
        <box><size>
          0.1 0.1 0.1
        </size></box>
      </geometry>
    </visual>

    <collision name="imu_link_collision">
      <geometry>
        <box><size>
          0.1 0.1 0.1
        </size></box>
      </geometry>
    </collision>

    <xacro:box_inertia m="0.1" w="0.1" d="0.1" h="0.1"/>

    <sensor name="imu_sensor" type="imu">
      <always_on>true</always_on>
      <update_rate>100</update_rate>
      <visualize>true</visualize>
      <topic>demo/imu</topic>
      <gz_frame_id>imu_link</gz_frame_id>
      <imu>
        <angular_velocity>
          <x>
            <noise type="gaussian">
              <mean>0.0</mean>
              <stddev>2e-4</stddev>
              <bias_mean>0.0000075</bias_mean>
              <bias_stddev>0.0000008</bias_stddev>
            </noise>
          </x>
          <y>
            <noise type="gaussian">
              <mean>0.0</mean>
              <stddev>2e-4</stddev>
              <bias_mean>0.0000075</bias_mean>
              <bias_stddev>0.0000008</bias_stddev>
            </noise>
          </y>
          <z>
            <noise type="gaussian">
              <mean>0.0</mean>
              <stddev>2e-4</stddev>
              <bias_mean>0.0000075</bias_mean>
              <bias_stddev>0.0000008</bias_stddev>
            </noise>
          </z>
        </angular_velocity>
        <linear_acceleration>
          <x>
            <noise type="gaussian">
              <mean>0.0</mean>
              <stddev>1.7e-2</stddev>
              <bias_mean>0.1</bias_mean>
              <bias_stddev>0.001</bias_stddev>
            </noise>
          </x>
          <y>
            <noise type="gaussian">
              <mean>0.0</mean>
              <stddev>1.7e-2</stddev>
              <bias_mean>0.1</bias_mean>
              <bias_stddev>0.001</bias_stddev>
            </noise>
          </y>
          <z>
            <noise type="gaussian">
              <mean>0.0</mean>
              <stddev>1.7e-2</stddev>
              <bias_mean>0.1</bias_mean>
              <bias_stddev>0.001</bias_stddev>
            </noise>
          </z>
        </linear_acceleration>
      </imu>
    </sensor>
  </link>

  <!-- lidar -->
  <joint name="lidar_joint" type="fixed">
    <parent>head_link</parent>
    <child>lidar_link</child>
    <pose relative_to="head_link">0.17 -0.17 ${(0.025 + base_height)/2} 0 0 ${pi/2}</pose>
  </joint>

  <link name='lidar_link'>
    <pose relative_to="lidar_joint"/>
    <visual name="lidar_link_visual">
      <geometry>
        <cylinder>
          <radius>0.0508</radius>
          <length>0.055</length>
        </cylinder>
      </geometry>
    </visual>

    <collision name="lidar_link_collision">
      <geometry>
        <cylinder>
          <radius>0.0508</radius>
          <length>0.055</length>
        </cylinder>
      </geometry>
    </collision>

    <xacro:cylinder_inertia m="0.125" r="0.0508" h="0.055"/>

    <sensor name="lidar" type="gpu_lidar">
      <always_on>true</always_on>
      <visualize>true</visualize>
      <update_rate>5</update_rate>
      <topic>scan</topic>
      <gz_frame_id>lidar_link</gz_frame_id>
      <lidar>
        <scan>
          <horizontal>
            <samples>360</samples>
            <resolution>1.000000</resolution>
            <min_angle>0.000000</min_angle>
            <max_angle>6.280000</max_angle>
          </horizontal>
        </scan>
        <range>
          <min>0.120000</min>
          <max>3.5</max>
          <resolution>0.015000</resolution>
        </range>
        <noise>
          <type>gaussian</type>
          <mean>0.0</mean>
          <stddev>0.01</stddev>
        </noise>
      </lidar>
    </sensor>
  </link>

  <!-- camera -->
  <joint name="camera_joint" type="fixed">
    <parent>pitch_turret_link</parent>
    <child>camera_link</child>
    <pose relative_to="base_link">0 ${head_width} 0.25 0 0 ${pi/2}</pose>
  </joint>

  <link name='camera_link'>
    <pose relative_to="camera_joint"/>
    <visual name="camera_link_visual">
      <geometry>
        <box><size>
          0.015 0.130 0.0222
        </size></box>
      </geometry>
    </visual>

    <collision name="camera_link_collision">
      <geometry>
        <box><size>
          0.015 0.130 0.0222
        </size></box>
      </geometry>
    </collision>

    <xacro:box_inertia m="0.035" w="0.015" d="0.130" h="0.0222"/>

    <sensor name="depth_camera" type="rgbd_camera">
      <always_on>true</always_on>
      <visualize>true</visualize>
      <update_rate>5.0</update_rate>
      <topic>depth_camera</topic>
      <gz_frame_id>camera_link</gz_frame_id>
      <camera>
        <horizontal_fov>1.047198</horizontal_fov>
        <image>
          <width>640</width>
          <height>480</height>
        </image>
        <clip>
          <near>0.05</near>
          <far>3</far>
        </clip>
      </camera>
      <baseline>0.2</baseline>
      <pointCloudCutoff>0.5</pointCloudCutoff>
      <pointCloudCutoffMax>3.0</pointCloudCutoffMax>
      <distortionK1>0</distortionK1>
      <distortionK2>0</distortionK2>
      <distortionK3>0</distortionK3>
      <distortionT1>0</distortionT1>
      <distortionT2>0</distortionT2>
      <CxPrime>0</CxPrime>
      <Cx>0</Cx>
      <Cy>0</Cy>
      <focalLength>0</focalLength>
      <hackBaseline>0</hackBaseline>
    </sensor>
  </link>

  </model>
</sdf>
