<?xml version="1.0"?>
<!--URDF generated by ONSHAPE BY PTC INC, 1.217-->
<robot name="sentry_pkg">
  <link name="body">
    <inertial>
      <mass value="0.0507536"/>
      <origin xyz="-2.33205e-05 -3.02404e-05 0.160359" rpy="0 -0 0"/>
      <inertia ixx="0.00127958" ixy="3.57925e-11" ixz="-1.40827e-07" iyy="0.00127958" iyz="-1.82614e-07" izz="0.00226416"/>
    </inertial>
    <visual>
      <origin xyz="0 -1.82166e-17 0.0734155" rpy="0 -0 0"/>
      <geometry>
        <mesh filename="package://sentry_pkg/meshes/Body.stl" scale="1 1 1"/>
      </geometry>
      <material name="0.615686_0.811765_0.929412_0.000000_0.000000">
        <color rgba="0.615686 0.811765 0.929412 1"/>
      </material>
    </visual>
    <collision>
      <origin xyz="0 0 0" rpy="0 0 0"/>
      <geometry>
        <cylinder radius="0.03" length="0.01"/>
      </geometry>
    </collision>
  </link>
  <link name="head">
    <inertial>
      <mass value="0.00414744"/>
      <origin xyz="-0.00211769 -0.00164536 0.0741316" rpy="0 -0 1.18195"/>
      <inertia ixx="2.08028e-05" ixy="-3.50322e-06" ixz="-4.24357e-08" iyy="1.60288e-05" iyz="-3.29709e-08" izz="2.21034e-05"/>
    </inertial>
    <visual>
      <origin xyz="-2.54975e-18 1.04465e-18 0" rpy="0 -0 1.18195"/>
      <geometry>
        <mesh filename="package://sentry_pkg/meshes/Head.stl" scale="1 1 1"/>
      </geometry>
      <material name="0.615686_0.811765_0.929412_0.000000_0.000000">
        <color rgba="0.615686 0.811765 0.929412 1"/>
      </material>
    </visual>
  </link>
  <link name="lidar">
    <inertial>
      <mass value="0.00018588"/>
      <origin xyz="2.43997e-19 -6.96211e-19 0.02065" rpy="0 -0 1.90788"/>
      <inertia ixx="9.29949e-08" ixy="0" ixz="0" iyy="9.29949e-08" iyz="0" izz="1.33148e-07"/>
    </inertial>
    <visual>
      <origin xyz="2.18721e-18 7.6654e-19 0" rpy="0 -0 1.90788"/>
      <geometry>
        <mesh filename="package://sentry_pkg/meshes/Lidar.stl" scale="1 1 1"/>
      </geometry>
      <material name="0.615686_0.811765_0.929412_0.000000_0.000000">
        <color rgba="0.615686 0.811765 0.929412 1"/>
      </material>
    </visual>
  </link>
  <link name="odowheel">
    <inertial>
      <mass value="3.2572e-05"/>
      <origin xyz="0 0.009 4.67781e-19" rpy="0 -0 0"/>
      <inertia ixx="5.56982e-09" ixy="0" ixz="0" iyy="9.38075e-09" iyz="0" izz="5.56982e-09"/>
    </inertial>
    <visual>
      <origin xyz="0 0.009 -1.46958e-18" rpy="0 -0 0"/>
      <geometry>
        <mesh filename="package://sentry_pkg/meshes/OdoWheel.stl" scale="1 1 1"/>
      </geometry>
      <material name="0.615686_0.811765_0.929412_0.000000_0.000000">
        <color rgba="0.615686 0.811765 0.929412 1"/>
      </material>
    </visual>
    <collision>
      <origin xyz="0 0 0" rpy="1.5707 0 0"/>
      <geometry>
        <cylinder radius="0.024" length="0.018"/>
      </geometry>
    </collision>
  </link>
  <link name="odowheel_1">
    <inertial>
      <mass value="3.2572e-05"/>
      <origin xyz="0 0.009 4.67781e-19" rpy="0 -0 0"/>
      <inertia ixx="5.56982e-09" ixy="0" ixz="0" iyy="9.38075e-09" iyz="0" izz="5.56982e-09"/>
    </inertial>
    <visual>
      <origin xyz="0 0.009 -1.46958e-18" rpy="0 -0 0"/>
      <geometry>
        <mesh filename="package://sentry_pkg/meshes/OdoWheel.stl" scale="1 1 1"/>
      </geometry>
      <material name="0.615686_0.811765_0.929412_0.000000_0.000000">
        <color rgba="0.615686 0.811765 0.929412 1"/>
      </material>
    </visual>
    <collision>
      <origin xyz="0 0 0" rpy="1.5707 0 0"/>
      <geometry>
        <cylinder radius="0.024" length="0.018"/>
      </geometry>
    </collision>
  </link>
  <link name="root"/>
  <joint name="fastened_2" type="fixed">
    <origin xyz="0 0 0" rpy="0 -0 3.14159"/>
    <axis xyz="-0 -0 -1"/>
    <parent link="root"/>
    <child link="body"/>
  </joint>
  <joint name="headlink" type="continuous">
    <origin xyz="-2.54975e-18 5.65558e-17 0.252215" rpy="0 -0 3.14159"/>
    <axis xyz="0 0 -1"/>
    <parent link="body"/>
    <child link="head"/>
  </joint>
  <joint name="lidarlink" type="fixed">
    <origin xyz="-0.170562 -0.139254 0.0718" rpy="0 0 -1.95964"/>
    <parent link="head"/>
    <child link="lidar"/>
  </joint>
  <joint name="odowheel_x" type="continuous">
    <origin xyz="-0.089012 -0.009 0.0286405" rpy="3.14159 -0 3.14159"/>
    <axis xyz="0 -1 0"/>
    <parent link="body"/>
    <child link="odowheel"/>
  </joint>
  <joint name="odowheel_y" type="continuous">
    <origin xyz="0.014 -0.089012 0.0286405" rpy="0 0 -1.5708"/>
    <axis xyz="0 -1 0"/>
    <parent link="body"/>
    <child link="odowheel_1"/>
  </joint>
  <gazebo reference="lidar">
    <sensor name="lidar" type="gpu_lidar">
      <always_on>true</always_on>
      <visualize>true</visualize>
      <update_rate>10</update_rate>
      <topic>scan</topic>
      <gz_frame_id>lidar</gz_frame_id>
      <lidar>
        <scan>
          <horizontal>
            <samples>360</samples>
            <resolution>1.000000</resolution>
            <min_angle>0.000000</min_angle>
            <max_angle>6.280000</max_angle>
          </horizontal>
        </scan>
        <range>
          <min>0.120000</min>
          <max>3.5</max>
          <resolution>0.015000</resolution>
        </range>
        <noise>
          <type>gaussian</type>
          <mean>0.0</mean>
          <stddev>0.01</stddev>
        </noise>
      </lidar>
    </sensor>
  </gazebo>
  <gazebo>
    <plugin filename="ignition-gazebo-odometry-publisher-system" name="ignition::gazebo::systems::OdometryPublisher">
      <odom_frame>odom</odom_frame>
      <robot_base_frame>root</robot_base_frame>
      <publish_odom_tf>true</publish_odom_tf>
      <dimensions>3</dimensions>
    </plugin>
    <plugin filename="ignition-gazebo-joint-state-publisher-system" name="ignition::gazebo::systems::JointStatePublisher">
      <joint_name>headlink</joint_name>
      <joint_name>odowheel_x</joint_name>
      <joint_name>odowheel_y</joint_name>
    </plugin>
  </gazebo>
</robot>
