<?xml version="1.0"?>
<!--URDF generated by ONSHAPE BY PTC INC, 1.217-->
<robot name="sentry_pkg">
  <link name="base_footprint"/>
  <link name="body">
    <inertial>
      <mass value="0.0701287"/>
      <origin xyz="1.20374e-17 2.46519e-32 0.126108" rpy="0 -0 0"/>
      <inertia ixx="0.00192346" ixy="0" ixz="0" iyy="0.00192346" iyz="0" izz="0.00310341"/>
    </inertial>
    <visual>
      <origin xyz="0 -1.82166e-17 0.0734155" rpy="0 -0 0"/>
      <geometry>
        <mesh filename="package://sentry_pkg/meshes/Body.stl" scale="1 1 1"/>
      </geometry>
      <material name="0.615686_0.811765_0.929412_0.000000_0.000000">
        <color rgba="0.615686 0.811765 0.929412 1"/>
      </material>
    </visual>
    <collision>
      <origin xyz="0 0 0.01" rpy="0 0 0"/>
      <geometry>
        <box size="0.3 0.3 0.02"/>
      </geometry>
    </collision>
  </link>
  <link name="head">
    <inertial>
      <mass value="0.00414744"/>
      <origin xyz="-0.00211769 -0.00164536 0.0741316" rpy="0 -0 1.18195"/>
      <inertia ixx="2.08028e-05" ixy="-3.50322e-06" ixz="-4.24357e-08" iyy="1.60288e-05" iyz="-3.29709e-08" izz="2.21034e-05"/>
    </inertial>
    <visual>
      <origin xyz="-2.54975e-18 1.04465e-18 0" rpy="0 -0 1.18195"/>
      <geometry>
        <mesh filename="package://sentry_pkg/meshes/Head.stl" scale="1 1 1"/>
      </geometry>
      <material name="0.615686_0.811765_0.929412_0.000000_0.000000">
        <color rgba="0.615686 0.811765 0.929412 1"/>
      </material>
    </visual>
  </link>
  <link name="lidar">
    <inertial>
      <mass value="0.00018588"/>
      <origin xyz="2.43997e-19 -6.96211e-19 0.02065" rpy="0 -0 1.90788"/>
      <inertia ixx="9.29949e-08" ixy="0" ixz="0" iyy="9.29949e-08" iyz="0" izz="1.33148e-07"/>
    </inertial>
    <visual>
      <origin xyz="2.18721e-18 7.6654e-19 0" rpy="0 -0 1.90788"/>
      <geometry>
        <mesh filename="package://sentry_pkg/meshes/Lidar.stl" scale="1 1 1"/>
      </geometry>
      <material name="0.615686_0.811765_0.929412_0.000000_0.000000">
        <color rgba="0.615686 0.811765 0.929412 1"/>
      </material>
    </visual>
  </link>
  <joint name="base_joint" type="fixed">
    <parent link="base_footprint"/>
    <child link="body"/>
    <origin xyz="0.0 0.0 0.0" rpy="0 0 0"/>
  </joint>
  <joint name="headlink" type="continuous">
    <origin xyz="-2.54975e-18 5.65558e-17 0.252215" rpy="0 -0 3.14159"/>
    <axis xyz="0 0 -1"/>
    <parent link="body"/>
    <child link="head"/>
  </joint>
  <joint name="lidarlink" type="continuous">
    <origin xyz="-0.170562 -0.139254 0.0718" rpy="0 0 -1.95964"/>
    <axis xyz="0 0 -1"/>
    <parent link="head"/>
    <child link="lidar"/>
  </joint>
  <gazebo reference="lidar">
    <sensor name="lidar" type="gpu_lidar">
      <always_on>true</always_on>
      <visualize>true</visualize>
      <update_rate>5</update_rate>
      <topic>scan</topic>
      <gz_frame_id>lidar</gz_frame_id>
      <lidar>
        <scan>
          <horizontal>
            <samples>360</samples>
            <resolution>1.000000</resolution>
            <min_angle>0.000000</min_angle>
            <max_angle>6.280000</max_angle>
          </horizontal>
        </scan>
        <range>
          <min>0.120000</min>
          <max>3.5</max>
          <resolution>0.015000</resolution>
        </range>
        <noise>
          <type>gaussian</type>
          <mean>0.0</mean>
          <stddev>0.01</stddev>
        </noise>
      </lidar>
    </sensor>
  </gazebo>
</robot>
